<?xml version="1.0"?>
<robot xmlns:xacro="http://www.ros.org/wiki/xacro">
    <link name="br_hip">
        <visual>
            <origin rpy="0 0 ${PI}" xyz="-0.05 0 0" />
            <geometry>
                <mesh filename="package://spiderbot_description/meshes/m_coxa_flbr.stl"
                    scale="0.01 0.01 0.01" />
            </geometry>
            <material name="blue" />
        </visual>
    </link>

    <joint name="joint_h_br" type="revolute">
        <parent link="base_link" />
        <child link="br_hip" />
        <origin rpy="0 0 ${PI}" xyz="0.4 -0.37 0.06" />
        <axis xyz="0 0 1"/>
        <limit lower="-${PI/2}" upper="${PI/4}" effort="${effort}" velocity="${velocity}" />
    </joint>

    <link name="br_femur">
        <visual>
            <origin rpy="0 0 ${PI}" xyz="-0.08 0.23 0.0" />
            <geometry>
                <mesh filename="package://spiderbot_description/meshes/m_femur_flbr.stl"
                    scale="0.01 0.01 0.01" />
            </geometry>
            <material name="green" />
        </visual>
    </link>

    <joint name="joint_hip_femur_br" type="revolute">
        <parent link="br_hip" />
        <child link="br_femur" />
        <origin rpy="0 0 ${PI/2}" xyz="-0.33 0.0 0.03" />
        <axis xyz="1 0 0"/>
        <limit lower="-${PI/4}" upper="${PI/2}" effort="${effort}" velocity="${velocity}" />
    </joint>

    
    <link name="br_tibia">
        <visual>
            <origin rpy="${PI} ${PI} ${PI}" xyz="0.01 0.26 0.0" />
            <geometry>
                <mesh filename="package://spiderbot_description/meshes/m_tibia_flbr.stl"
                    scale="0.01 0.01 0.01" />
            </geometry>
            <material name="pink" />
        </visual>
    </link>

    <joint name="joint_femur_tibia_br" type="revolute">
        <parent link="br_femur" />
        <child link="br_tibia" />
        <origin rpy="0 0 0" xyz="0.0 0.46 0" />
        <axis xyz="1 0 0"/>
        <limit lower="-${4*PI/5}" upper="0" effort="${effort}" velocity="${velocity}" />
    </joint>
</robot>