<?xml version="1.0"?>
<robot xmlns:xacro="http://www.ros.org/wiki/xacro">
    <link name="bl_hip">
        <xacro:default_inertial mass="0.02" />
        <visual>
            <origin rpy="${PI} 0 0" xyz="-0.05 0 0" />
            <geometry>
                <mesh filename="package://spiderbot_description/meshes/m_coxa_frbl.stl"
                    scale="0.01 0.01 0.01" />
            </geometry>
            <material name="orange" />
        </visual>
        <collision>
            <origin rpy="${PI} 0 0" xyz="-0.05 0 0" />
            <geometry>
                <mesh filename="package://spiderbot_description/meshes/m_coxa_frbl.stl"
                    scale="0.01 0.01 0.01" />
            </geometry>
            <material name="orange" />
        </collision>
    </link>

    <joint name="joint_h_bl" type="revolute">
        <parent link="base_link" />
        <child link="bl_hip" />
        <origin rpy="${PI} 0 0" xyz="-0.4 -0.37 0.06" />
        <axis xyz="0 0 1"/>
        <limit lower="-${PI/2}" upper="${PI/4}" effort="${effort}" velocity="${velocity}" />
    </joint>

    
    <link name="bl_femur">
        <xacro:default_inertial mass="0.02" />
        <visual>
            <origin rpy="${PI} 0 ${PI}" xyz="0.08 -0.23 0.0" />
            <geometry>
                <mesh filename="package://spiderbot_description/meshes/m_femur_frbl.stl"
                    scale="0.01 0.01 0.01" />
            </geometry>
            <material name="yellow" />
        </visual>
        <collision>
            <origin rpy="${PI} 0 ${PI}" xyz="0.08 -0.23 0.0" />
            <geometry>
                <mesh filename="package://spiderbot_description/meshes/m_femur_frbl.stl"
                    scale="0.01 0.01 0.01" />
            </geometry>
            <material name="yellow" />
        </collision>
    </link>

    <joint name="joint_hip_femur_bl" type="revolute">
        <parent link="bl_hip" />
        <child link="bl_femur" />
        <origin rpy="0 0 ${-PI/2}" xyz="-0.33 0.0 -0.03" />
        <axis xyz="1 0 0"/>
        <limit lower="-${PI/4}" upper="${PI/2}" effort="${effort}" velocity="${velocity}" />
    </joint>

    <link name="bl_tibia">
        <xacro:default_inertial mass="0.02" />
        <visual>
            <origin rpy="${PI} 0 0" xyz="0.01 -0.26 0.0" />
            <geometry>
                <mesh filename="package://spiderbot_description/meshes/m_tibia_frbl.stl"
                    scale="0.01 0.01 0.01" />
            </geometry>
            <material name="purple" />
        </visual>
        <collision>
            <origin rpy="${PI} 0 0" xyz="0.01 -0.26 0.0" />
            <geometry>
                <mesh filename="package://spiderbot_description/meshes/m_tibia_frbl.stl"
                    scale="0.01 0.01 0.01" />
            </geometry>
            <material name="purple" />
        </collision>
    </link>

    <joint name="joint_femur_tibia_bl" type="revolute">
        <parent link="bl_femur" />
        <child link="bl_tibia" />
        <origin rpy="0 0 0" xyz="0.0 -0.46 0" />
        <axis xyz="1 0 0"/>
        <limit lower="-${4*PI/5}" upper="0" effort="${effort}" velocity="${velocity}" />
    </joint>
</robot>