<?xml version="1.0"?>
<robot xmlns:xacro="http://www.ros.org/wiki/xacro">

    <link name="fl_hip">
        <xacro:default_inertial mass="0.02" />
        <visual>
            <origin rpy="${PI} 0 ${PI}" xyz="-0.05 0 0" />
            <geometry>
                <mesh filename="package://spiderbot_description/meshes/m_coxa_flbr.stl"
                    scale="0.01 0.01 0.01" />
            </geometry>
            <material name="blue" />
        </visual>
        <collision>
            <origin rpy="${PI} 0 ${PI}" xyz="-0.05 0 0" />
            <geometry>
                <mesh filename="package://spiderbot_description/meshes/m_coxa_flbr.stl"
                    scale="0.01 0.01 0.01" />
            </geometry>
        </collision>
    </link>

    <joint name="joint_h_fl" type="revolute">
        <parent link="robot_body" />
        <child link="fl_hip" />
        <origin rpy="${PI} 0 0" xyz="-0.4 0.37 0.06" />
        <axis xyz="0 0 1"/>
        <limit lower="-${PI/4}" upper="${PI/2}" effort="${effort}" velocity="${velocity}" />
    </joint>

    <link name="fl_femur">
        <xacro:default_inertial mass="0.02" />
        <visual>
            <origin rpy="${PI} 0 ${PI}" xyz="-0.08 -0.23 0.0" />
            <geometry>
                <mesh filename="package://spiderbot_description/meshes/m_femur_flbr.stl"
                    scale="0.01 0.01 0.01" />
            </geometry>
            <material name="yellow" />
        </visual>
        <collision>
            <origin rpy="${PI} 0 ${PI}" xyz="-0.08 -0.23 0.0" />
            <geometry>
                <mesh filename="package://spiderbot_description/meshes/m_femur_flbr.stl"
                    scale="0.01 0.01 0.01" />
            </geometry>
        </collision>
    </link>

    <joint name="joint_hip_femur_fl" type="revolute">
        <parent link="fl_hip" />
        <child link="fl_femur" />
        <origin rpy="0 0 ${-PI/2}" xyz="-0.33 0.0 -0.03" />
        <axis xyz="1 0 0"/>
        <limit lower="-${PI/4}" upper="${PI/2}" effort="${effort}" velocity="${velocity}" />
    </joint>

    <link name="fl_tibia">
        <xacro:default_inertial mass="0.02" />
        <visual>
            <origin rpy="${PI} 0 0" xyz="-0.01 -0.26 0.0" />
            <geometry>
                <mesh filename="package://spiderbot_description/meshes/m_tibia_flbr.stl"
                    scale="0.01 0.01 0.01" />
            </geometry>
            <material name="red" />
        </visual>
        <collision>
            <origin rpy="${PI} 0 0" xyz="-0.01 -0.26 0.0" />
            <geometry>
                <mesh filename="package://spiderbot_description/meshes/m_tibia_flbr.stl"
                    scale="0.01 0.01 0.01" />
            </geometry>
        </collision>
    </link>

    <joint name="joint_femur_tibia_fl" type="revolute">
        <parent link="fl_femur" />
        <child link="fl_tibia" />
        <origin rpy="0 0 0" xyz="0.0 -0.46 0" />
        <axis xyz="1 0 0"/>
        <limit lower="-${4*PI/5}" upper="0" effort="${effort}" velocity="${velocity}" />
    </joint>
</robot>